<robot name="thor">

  <!-- TODO: None of the mass or inertia values are correct...-->
  <!-- TODO: also no collision information... how can we fix this?-->

    <link name="base">
      <visual>
        <origin xyz="0 0 0" rpy="0 0 0"/>
        <geometry>
          <mesh filename="thor_meshes/base.stl" scale="0.001 0.001 0.001" />
        </geometry>
        <material name="base">
          <color rgba="0.0 0.0 0.0 1.0"/> 
        </material>
      </visual>
      <inertial>
        <mass value="10"/>
        <inertia ixx="0.4" ixy="0.0" ixz="0.0" iyy="0.4" iyz="0.0" izz="0.2"/>
      </inertial>
    </link>

    <joint name="art1_yaw" type="revolute">
      <origin xyz="0 0 0.104" rpy="0 0 0"/>
      <axis xyz="0 0 1"/>
      <parent link="base"/>
      <child link="art1"/>
      <limit lower="-3.1415" upper="3.1415" effort="4" velocity="1" />
    </joint>

    <link name="art1">
      <visual>
	      <origin xyz="0 0 0" rpy="0 0 0" />
	      <geometry>
	        <mesh filename="thor_meshes/art1.stl" scale="0.001 0.001 0.001" />
	      </geometry>
	      <material name="red">
          <color rgba="1.0 0.0 0.0 1.0"/> 
        </material>
      </visual>
      <inertial>
        <mass value="10"/>
        <inertia ixx="0.4" ixy="0.0" ixz="0.0" iyy="0.4" iyz="0.0" izz="0.2"/>
      </inertial>
    </link>

    <joint name="art2_pitch" type="revolute">
      <origin xyz="0 -0.0318752 0.0974304" rpy="1.5707963267948966 -1.5707963267948966 0"/>
	    <axis xyz="0 0 1"/>
	    <parent link="art1"/>
      <child link="art2"/>
	    <limit lower="-1.5707963267948966" upper="1.5707963267948966" effort="4" velocity="1" />
    </joint>

    <link name="art2">
      <visual>
	      <origin xyz="0 0 0" rpy="0 0 0" />
	      <geometry>
	        <mesh filename="thor_meshes/art2.stl" scale="0.001 0.001 0.001" />
	      </geometry>
	      <material name="black">
          <color rgba="0.0 0.0 0.0 1.0"/> 
        </material>
      </visual>
      <inertial>
        <mass value="10"/>
        <inertia ixx="0.4" ixy="0.0" ixz="0.0" iyy="0.4" iyz="0.0" izz="0.2"/>
      </inertial>
    </link>

    <joint name="art3_pitch" type="revolute">
      <origin xyz="0.160 0 0" rpy="0 0 0"/>
      <axis xyz="0 0 1"/>
      <parent link="art2"/>
      <child link="art3"/>
      <limit lower="-1.5707963267948966" upper="1.5707963267948966" effort="4" velocity="1" />
    </joint>

    <link name="art3">
      <visual>
	      <origin xyz="0 0 0" rpy="0 0 0" />
	      <geometry>
	        <mesh filename="thor_meshes/art3.stl" scale="0.001 0.001 0.001" />
	      </geometry>
	      <material name="red"/>
      </visual>
      <inertial>
        <mass value="10"/>
        <inertia ixx="0.4" ixy="0.0" ixz="0.0" iyy="0.4" iyz="0.0" izz="0.2"/>
      </inertial>
    </link>

    <joint name="art4_roll" type="revolute">
      <origin xyz="0.0885 0 -0.035" rpy="0 1.5707963267948966 0"/>
      <axis xyz="0 0 1"/>
      <parent link="art3"/>
      <child link="art4"/>
      <limit lower="-3.1415" upper="3.1415" effort="4" velocity="1" />
    </joint>

    <link name="art4">
      <visual>
	      <origin xyz="0 0 0" rpy="0 0 0" />
	      <geometry>
	        <mesh filename="thor_meshes/art4.stl" scale="0.001 0.001 0.001" />
	      </geometry>
	      <material name="red2">
          <color rgba="0.85 0.0 0.0 1.0"/>
        </material>
      </visual>
      <inertial>
        <mass value="10"/>
        <inertia ixx="0.4" ixy="0.0" ixz="0.0" iyy="0.4" iyz="0.0" izz="0.2"/>
      </inertial>
    </link>

    <joint name="art5_pitch" type="revolute">
      <origin xyz="0 0 0.1" rpy="0 -1.5707963267948966 0"/>
      <axis xyz="0 0 1"/>
      <parent link="art4"/>
      <child link="art5"/>
      <limit lower="-1.5" upper="1.5" effort="4" velocity="1" /> <!-- Slightly less than right angle -->
    </joint>

    <link name="art5">
      <visual>
	      <origin xyz="0 0 0" rpy="0 0 0" />
	      <geometry>
	        <mesh filename="thor_meshes/art5.stl" scale="0.001 0.001 0.001" />
	      </geometry>
	      <material name="black"/>
      </visual>
      <inertial>
        <mass value="10"/>
        <inertia ixx="0.4" ixy="0.0" ixz="0.0" iyy="0.4" iyz="0.0" izz="0.2"/>
      </inertial>
    </link>

    <joint name="art6_roll" type="revolute">
      <origin xyz="0 0 0" rpy="0 1.5707963267948966 0"/>
      <axis xyz="0 0 1"/>
      <parent link="art5"/>
      <child link="art6"/>
      <limit lower="-3.1415" upper="3.1415" effort="4" velocity="1" />
    </joint>

    <link name="art6">
      <visual>
	      <origin xyz="0 0 0" rpy="0 0 0" />
	      <geometry>
	        <mesh filename="thor_meshes/art6.stl" scale="0.001 0.001 0.001" />
	      </geometry>
	      <material name="black"/>
      </visual>
      <inertial>
        <mass value="10"/>
        <inertia ixx="0.4" ixy="0.0" ixz="0.0" iyy="0.4" iyz="0.0" izz="0.2"/>
      </inertial>
    </link>

</robot>
